#VRML_SIM R2025a utf8

PROTO Viper [
  field SFVec3f translation -0.35 0 0.055
  field SFRotation rotation 0 0 1 0
  field SFString name "viper"
  field SFString controller "robot_controller"
]
{
  Robot {
    translation IS translation
    rotation IS rotation
    name IS name
    controller IS controller
    model "Viper three omniwheel robot"

    children [
      GPS {
      }

      InertialUnit {
        name "IMU"
      }

      # IPC — channel 0: receive actions from supervisor
      #        channel 1: send lidar + robot_id to supervisor
      Receiver {
        name "receiver"
        channel 0
      }

      Emitter {
        name "emitter"
        channel 1
      }

      DEF BODY_TRANS Pose {
        translation 0 0 0.030
        children [
          Shape {
            appearance PBRAppearance {
              baseColor 0.015 0.015 0.018
              roughness 0.42
              metalness 0.15
            }
            geometry Cylinder {
              height 0.060
              radius 0.120
              subdivision 64
            }
          }
        ]
      }

      Pose {
        translation 0 0 0.033
        children [
          Shape {
            appearance PBRAppearance {
              baseColor 0.95 0.02 0.02
              emissiveColor 0.35 0 0
              roughness 0.35
              metalness 0.05
            }
            geometry Cylinder {
              height 0.006
              radius 0.122
              subdivision 64
            }
          }
        ]
      }

      Pose {
        translation 0 0 0.066
        children [
          Shape {
            appearance PBRAppearance {
              baseColor 0.005 0.005 0.008
              roughness 0.36
              metalness 0.25
            }
            geometry Cylinder {
              height 0.013
              radius 0.080
              subdivision 64
            }
          }
        ]
      }

      Pose {
        translation 0 0 0.074
        children [
          Shape {
            appearance PBRAppearance {
              baseColor 0.95 0.02 0.02
              emissiveColor 0.25 0 0
              roughness 0.32
              metalness 0.05
            }
            geometry Cylinder {
              height 0.0035
              radius 0.083
              subdivision 64
            }
          }
        ]
      }

      Pose {
        translation 0.090 0 0.082
        children [
          Shape {
            appearance PBRAppearance {
              baseColor 0.82 0.82 0.86
              roughness 0.28
              metalness 0.2
            }
            geometry Box {
              size 0.038 0.022 0.007
            }
          }
        ]
      }

      Pose {
        translation 0.111 0 0.086
        children [
          Shape {
            appearance PBRAppearance {
              baseColor 1 0.02 0.02
              emissiveColor 0.45 0 0
              roughness 0.25
              metalness 0.1
            }
            geometry Box {
              size 0.005 0.026 0.004
            }
          }
        ]
      }

      Lidar {
        translation 0 0 0.100
        rotation 0 0 1 0
        name "lidar"
        horizontalResolution 360
        fieldOfView 6.28318
        numberOfLayers 1
        near 0.02
        minRange 0.02
        maxRange 3.5
        noise 0.01
      }

      Pose {
        translation 0 0 0.081
        children [
          Shape {
            appearance PBRAppearance {
              baseColor 0.01 0.01 0.01
              roughness 0.6
              metalness 0
            }
            geometry Cylinder {
              height 0.008
              radius 0.026
              subdivision 32
            }
          }
        ]
      }

      Pose {
        translation 0 0 0.093
        children [
          Shape {
            appearance PBRAppearance {
              baseColor 0.02 0.02 0.02
              roughness 0.6
              metalness 0
            }
            geometry Cylinder {
              height 0.017
              radius 0.014
              subdivision 32
            }
          }
        ]
      }

      # Wheel 1 - rear / base wheel
      Pose {
        rotation 0 0 1 0
        children [
          Pose {
            translation -0.102 0 0.030
            children [
              Shape {
                appearance PBRAppearance {
                  baseColor 0.01 0.01 0.01
                  roughness 0.8
                  metalness 0
                }
                geometry Box {
                  size 0.040 0.016 0.012
                }
              }
            ]
          }

          HingeJoint {
            jointParameters HingeJointParameters {
              axis 1 0 0
              anchor -0.138 0 0.030
            }
            device [
              RotationalMotor {
                name "wheel1"
                maxVelocity 20
                maxTorque 2.0
              }
            ]
            endPoint Solid {
              translation -0.138 0 0.030
              rotation 0 1 0 1.5708
              children [
                Shape {
                  appearance PBRAppearance {
                    baseColor 0.005 0.005 0.005
                    roughness 0.85
                    metalness 0
                  }
                  geometry Cylinder {
                    height 0.028
                    radius 0.030
                    subdivision 32
                  }
                }
                Pose {
                  translation 0 0 0.015
                  children [
                    Shape {
                      appearance PBRAppearance {
                        baseColor 0.22 0.22 0.24
                        roughness 0.32
                        metalness 0.45
                      }
                      geometry Cylinder {
                        height 0.0035
                        radius 0.018
                        subdivision 24
                      }
                    }
                  ]
                }
                Pose {
                  translation 0 0 -0.015
                  children [
                    Shape {
                      appearance PBRAppearance {
                        baseColor 0.22 0.22 0.24
                        roughness 0.32
                        metalness 0.45
                      }
                      geometry Cylinder {
                        height 0.0035
                        radius 0.018
                        subdivision 24
                      }
                    }
                  ]
                }
              ]
              name "wheel1_solid"
              boundingObject Cylinder {
                height 0.028
                radius 0.030
              }
              physics Physics {
                density -1
                mass 0.05
              }
              contactMaterial "wheel"
            }
          }
        ]
      }

      # Wheel 2 - front right, rotated 120 degrees
      Pose {
        rotation 0 0 1 2.0944
        children [
          Pose {
            translation -0.102 0 0.030
            children [
              Shape {
                appearance PBRAppearance {
                  baseColor 0.01 0.01 0.01
                  roughness 0.8
                  metalness 0
                }
                geometry Box {
                  size 0.040 0.016 0.012
                }
              }
            ]
          }
          HingeJoint {
            jointParameters HingeJointParameters {
              axis 1 0 0
              anchor -0.138 0 0.030
            }
            device [
              RotationalMotor {
                name "wheel2"
                maxVelocity 20
                maxTorque 2.0
              }
            ]
            endPoint Solid {
              translation -0.138 0 0.030
              rotation 0 1 0 1.5708
              children [
                Shape {
                  appearance PBRAppearance {
                    baseColor 0.005 0.005 0.005
                    roughness 0.85
                    metalness 0
                  }
                  geometry Cylinder {
                    height 0.028
                    radius 0.030
                    subdivision 32
                  }
                }
                Pose {
                  translation 0 0 0.015
                  children [
                    Shape {
                      appearance PBRAppearance {
                        baseColor 0.22 0.22 0.24
                        roughness 0.32
                        metalness 0.45
                      }
                      geometry Cylinder {
                        height 0.0035
                        radius 0.018
                        subdivision 24
                      }
                    }
                  ]
                }
                Pose {
                  translation 0 0 -0.015
                  children [
                    Shape {
                      appearance PBRAppearance {
                        baseColor 0.22 0.22 0.24
                        roughness 0.32
                        metalness 0.45
                      }
                      geometry Cylinder {
                        height 0.0035
                        radius 0.018
                        subdivision 24
                      }
                    }
                  ]
                }
              ]
              name "wheel2_solid"
              boundingObject Cylinder {
                height 0.028
                radius 0.030
              }
              physics Physics {
                density -1
                mass 0.05
              }
              contactMaterial "wheel"
            }
          }
        ]
      }

      # Wheel 3 - front left, rotated 240 degrees
      Pose {
        rotation 0 0 1 4.1888
        children [
          Pose {
            translation -0.102 0 0.030
            children [
              Shape {
                appearance PBRAppearance {
                  baseColor 0.01 0.01 0.01
                  roughness 0.8
                  metalness 0
                }
                geometry Box {
                  size 0.040 0.016 0.012
                }
              }
            ]
          }
          HingeJoint {
            jointParameters HingeJointParameters {
              axis 1 0 0
              anchor -0.138 0 0.030
            }
            device [
              RotationalMotor {
                name "wheel3"
                maxVelocity 20
                maxTorque 2.0
              }
            ]
            endPoint Solid {
              translation -0.138 0 0.030
              rotation 0 1 0 1.5708
              children [
                Shape {
                  appearance PBRAppearance {
                    baseColor 0.005 0.005 0.005
                    roughness 0.85
                    metalness 0
                  }
                  geometry Cylinder {
                    height 0.028
                    radius 0.030
                    subdivision 32
                  }
                }
                Pose {
                  translation 0 0 0.015
                  children [
                    Shape {
                      appearance PBRAppearance {
                        baseColor 0.22 0.22 0.24
                        roughness 0.32
                        metalness 0.45
                      }
                      geometry Cylinder {
                        height 0.0035
                        radius 0.018
                        subdivision 24
                      }
                    }
                  ]
                }
                Pose {
                  translation 0 0 -0.015
                  children [
                    Shape {
                      appearance PBRAppearance {
                        baseColor 0.22 0.22 0.24
                        roughness 0.32
                        metalness 0.45
                      }
                      geometry Cylinder {
                        height 0.0035
                        radius 0.018
                        subdivision 24
                      }
                    }
                  ]
                }
              ]
              name "wheel3_solid"
              boundingObject Cylinder {
                height 0.028
                radius 0.030
              }
              physics Physics {
                density -1
                mass 0.05
              }
              contactMaterial "wheel"
            }
          }
        ]
      }
    ]

    boundingObject USE BODY_TRANS

    physics Physics {
      density -1
      mass 0.8
      damping Damping {
        linear 0.25
        angular 0.35
      }
    }

    contactMaterial "robot"

    recognitionColors [
      0.95 0.02 0.02
    ]
  }
}
